# Creating Dummy Data

## Debugging

### TypeError: make_aware() got an unexpected keyword argument 'is_dst'

#### Problem

I tried to seed fake dummy data with using following command line in terminal using django-seed package.

```bash
python manage.py seed users --number=10
```

But then I got the following error.

```bash
Traceback (most recent call last):
  File "/Users/apensia/dev/knower-admin/manage.py", line 32, in <module>
    main()
  File "/Users/apensia/dev/knower-admin/manage.py", line 28, in main
    execute_from_command_line(sys.argv)
  File "/Users/apensia/dev/knower-admin/venv/lib/python3.11/site-packages/django/core/management/__init__.py", line 442, in execute_from_command_line
    utility.execute()
  File "/Users/apensia/dev/knower-admin/venv/lib/python3.11/site-packages/django/core/management/__init__.py", line 436, in execute
    self.fetch_command(subcommand).run_from_argv(self.argv)
  File "/Users/apensia/dev/knower-admin/venv/lib/python3.11/site-packages/django/core/management/base.py", line 413, in run_from_argv
    self.execute(*args, **cmd_options)
  File "/Users/apensia/dev/knower-admin/venv/lib/python3.11/site-packages/django/core/management/base.py", line 459, in execute
    output = self.handle(*args, **options)
             ^^^^^^^^^^^^^^^^^^^^^^^^^^^^^
  File "/Users/apensia/dev/knower-admin/venv/lib/python3.11/site-packages/django/core/management/base.py", line 646, in handle
    app_output = self.handle_app_config(app_config, **options)
                 ^^^^^^^^^^^^^^^^^^^^^^^^^^^^^^^^^^^^^^^^^^^^^
  File "/Users/apensia/dev/knower-admin/venv/lib/python3.11/site-packages/django_seed/management/commands/seed.py", line 63, in handle_app_config
    generated = seeder.execute()
                ^^^^^^^^^^^^^^^^
  File "/Users/apensia/dev/knower-admin/venv/lib/python3.11/site-packages/django_seed/seeder.py", line 250, in execute
    executed_entity = entity.execute(using, inserted_entities)
                      ^^^^^^^^^^^^^^^^^^^^^^^^^^^^^^^^^^^^^^^^
  File "/Users/apensia/dev/knower-admin/venv/lib/python3.11/site-packages/django_seed/seeder.py", line 157, in execute
    faker_data = {
                 ^
  File "/Users/apensia/dev/knower-admin/venv/lib/python3.11/site-packages/django_seed/seeder.py", line 158, in <dictcomp>
    field: format_field(field_format, inserted_entities)
           ^^^^^^^^^^^^^^^^^^^^^^^^^^^^^^^^^^^^^^^^^^^^^
  File "/Users/apensia/dev/knower-admin/venv/lib/python3.11/site-packages/django_seed/seeder.py", line 144, in format_field
    return format(inserted_entities)
           ^^^^^^^^^^^^^^^^^^^^^^^^^
  File "/Users/apensia/dev/knower-admin/venv/lib/python3.11/site-packages/django_seed/guessers.py", line 120, in <lambda>
    return lambda x: _timezone_format(faker.date_time())
                     ^^^^^^^^^^^^^^^^^^^^^^^^^^^^^^^^^^^
  File "/Users/apensia/dev/knower-admin/venv/lib/python3.11/site-packages/django_seed/guessers.py", line 21, in _timezone_format
    return timezone.make_aware(value, timezone.get_current_timezone(), is_dst=False)
           ^^^^^^^^^^^^^^^^^^^^^^^^^^^^^^^^^^^^^^^^^^^^^^^^^^^^^^^^^^^^^^^^^^^^^^^^^
TypeError: make_aware() got an unexpected keyword argument 'is_dst'
```

#### Analysis

While spectating issues created in django-seed Github repositories, other developers also experienced same error while creating DateTime data in Django version 5 or more.
This is because Django version 5 or later does not accept `is_dst` as an argument anymore.

#### Solution

According to [salimbyte's suggestion,](https://github.com/Brobin/django-seed/issues/119#issuecomment-2141574298), I solved the problem by setting
[`USE_TZ`](https://docs.djangoproject.com/en/dev/ref/settings/#std-setting-USE_TZ) value as `False`.

```py
# settings.py

USE_TZ = False
```
