# Railway로 배포하기

## Invalid HTTP_HOST header 이슈

### Problem

Railway로 Django API 서버를 등록하고자 하는 도중 Invalid HTTP_HOST header 이슈가 생겼다.

### Analysis

배포할 때 `ALLOWED_HOSTS`에 Railway API 호스트를 등록하는 것을 깜빡했었다.

### Solution

## Could not translate host name to address: nodename nor servname provided or not known

### Problem

Railway 내에 만든 임시 개발 DB를 연결하는 과정에서 문제가 생겼다.

```
System check identified no issues (0 silenced).
Exception in thread django-main-thread:
Traceback (most recent call last):
  File "/Users/apensia/dev/knower-api/venv/lib/python3.11/site-packages/django/db/backends/base/base.py", line 289, in ensure_connection
    self.connect()
  File "/Users/apensia/dev/knower-api/venv/lib/python3.11/site-packages/django/utils/asyncio.py", line 26, in inner
    return func(*args, **kwargs)
           ^^^^^^^^^^^^^^^^^^^^^
  File "/Users/apensia/dev/knower-api/venv/lib/python3.11/site-packages/django/db/backends/base/base.py", line 270, in connect
    self.connection = self.get_new_connection(conn_params)
                      ^^^^^^^^^^^^^^^^^^^^^^^^^^^^^^^^^^^^
  File "/Users/apensia/dev/knower-api/venv/lib/python3.11/site-packages/django/utils/asyncio.py", line 26, in inner
    return func(*args, **kwargs)
           ^^^^^^^^^^^^^^^^^^^^^
  File "/Users/apensia/dev/knower-api/venv/lib/python3.11/site-packages/django/db/backends/postgresql/base.py", line 275, in get_new_connection
    connection = self.Database.connect(**conn_params)
                 ^^^^^^^^^^^^^^^^^^^^^^^^^^^^^^^^^^^^
  File "/Users/apensia/dev/knower-api/venv/lib/python3.11/site-packages/psycopg2/__init__.py", line 122, in connect
    conn = _connect(dsn, connection_factory=connection_factory, **kwasync)
           ^^^^^^^^^^^^^^^^^^^^^^^^^^^^^^^^^^^^^^^^^^^^^^^^^^^^^^^^^^^^^^^
psycopg2.OperationalError: could not translate host name "dpg-clhb0bmf27hc739pr86g-a" to address: nodename nor servname provided, or not known


The above exception was the direct cause of the following exception:

Traceback (most recent call last):
  File "/Library/Frameworks/Python.framework/Versions/3.11/lib/python3.11/threading.py", line 1038, in _bootstrap_inner
    self.run()
  File "/Library/Frameworks/Python.framework/Versions/3.11/lib/python3.11/threading.py", line 975, in run
    self._target(*self._args, **self._kwargs)
  File "/Users/apensia/dev/knower-api/venv/lib/python3.11/site-packages/django/utils/autoreload.py", line 64, in wrapper
    fn(*args, **kwargs)
  File "/Users/apensia/dev/knower-api/venv/lib/python3.11/site-packages/django/core/management/commands/runserver.py", line 136, in inner_run
    self.check_migrations()
  File "/Users/apensia/dev/knower-api/venv/lib/python3.11/site-packages/django/core/management/base.py", line 574, in check_migrations
    executor = MigrationExecutor(connections[DEFAULT_DB_ALIAS])
               ^^^^^^^^^^^^^^^^^^^^^^^^^^^^^^^^^^^^^^^^^^^^^^^^
  File "/Users/apensia/dev/knower-api/venv/lib/python3.11/site-packages/django/db/migrations/executor.py", line 18, in __init__
    self.loader = MigrationLoader(self.connection)
                  ^^^^^^^^^^^^^^^^^^^^^^^^^^^^^^^^
  File "/Users/apensia/dev/knower-api/venv/lib/python3.11/site-packages/django/db/migrations/loader.py", line 58, in __init__
    self.build_graph()
  File "/Users/apensia/dev/knower-api/venv/lib/python3.11/site-packages/django/db/migrations/loader.py", line 235, in build_graph
    self.applied_migrations = recorder.applied_migrations()
                              ^^^^^^^^^^^^^^^^^^^^^^^^^^^^^
  File "/Users/apensia/dev/knower-api/venv/lib/python3.11/site-packages/django/db/migrations/recorder.py", line 81, in applied_migrations
    if self.has_table():
       ^^^^^^^^^^^^^^^^
  File "/Users/apensia/dev/knower-api/venv/lib/python3.11/site-packages/django/db/migrations/recorder.py", line 57, in has_table
    with self.connection.cursor() as cursor:
         ^^^^^^^^^^^^^^^^^^^^^^^^
  File "/Users/apensia/dev/knower-api/venv/lib/python3.11/site-packages/django/utils/asyncio.py", line 26, in inner
    return func(*args, **kwargs)
           ^^^^^^^^^^^^^^^^^^^^^
  File "/Users/apensia/dev/knower-api/venv/lib/python3.11/site-packages/django/db/backends/base/base.py", line 330, in cursor
    return self._cursor()
           ^^^^^^^^^^^^^^
  File "/Users/apensia/dev/knower-api/venv/lib/python3.11/site-packages/django/db/backends/base/base.py", line 306, in _cursor
    self.ensure_connection()
  File "/Users/apensia/dev/knower-api/venv/lib/python3.11/site-packages/django/utils/asyncio.py", line 26, in inner
    return func(*args, **kwargs)
           ^^^^^^^^^^^^^^^^^^^^^
  File "/Users/apensia/dev/knower-api/venv/lib/python3.11/site-packages/django/db/backends/base/base.py", line 288, in ensure_connection
    with self.wrap_database_errors:
  File "/Users/apensia/dev/knower-api/venv/lib/python3.11/site-packages/django/db/utils.py", line 91, in __exit__
    raise dj_exc_value.with_traceback(traceback) from exc_value
  File "/Users/apensia/dev/knower-api/venv/lib/python3.11/site-packages/django/db/backends/base/base.py", line 289, in ensure_connection
    self.connect()
  File "/Users/apensia/dev/knower-api/venv/lib/python3.11/site-packages/django/utils/asyncio.py", line 26, in inner
    return func(*args, **kwargs)
           ^^^^^^^^^^^^^^^^^^^^^
  File "/Users/apensia/dev/knower-api/venv/lib/python3.11/site-packages/django/db/backends/base/base.py", line 270, in connect
    self.connection = self.get_new_connection(conn_params)
                      ^^^^^^^^^^^^^^^^^^^^^^^^^^^^^^^^^^^^
  File "/Users/apensia/dev/knower-api/venv/lib/python3.11/site-packages/django/utils/asyncio.py", line 26, in inner
    return func(*args, **kwargs)
           ^^^^^^^^^^^^^^^^^^^^^
  File "/Users/apensia/dev/knower-api/venv/lib/python3.11/site-packages/django/db/backends/postgresql/base.py", line 275, in get_new_connection
    connection = self.Database.connect(**conn_params)
                 ^^^^^^^^^^^^^^^^^^^^^^^^^^^^^^^^^^^^
  File "/Users/apensia/dev/knower-api/venv/lib/python3.11/site-packages/psycopg2/__init__.py", line 122, in connect
    conn = _connect(dsn, connection_factory=connection_factory, **kwasync)
           ^^^^^^^^^^^^^^^^^^^^^^^^^^^^^^^^^^^^^^^^^^^^^^^^^^^^^^^^^^^^^^^
django.db.utils.OperationalError: could not translate host name "dpg-clhb0bmf27hc739pr86g-a" to address: nodename nor servname provided, or not known
```

### Analysis

에러 메세지의 중간에 보면 `psycopg2` 라이브러리에서 문제가 생긴 건줄 알았지만 호스트 이름이 잘못된 것을 보고는 DB의 URL 주소가 잘못되었음을 발견했다.
생각해보니 예전에 [Render](https://render.com/)로 배포를 하려다가 유료로 전환되는 바람에 Railway로 갈아탔었는데 그 때 환경변수 내에 설정한 DB URL을 바꾸지 않았던 것이 화근이었다.

### Solution

환경변수 파일에서 올바른 Railway DB 주소를 기입했다.

## CSRF Authentication Failed

### Problem

어드민 페이지에 들어가려고 했더니 CSRF 검증에 실패하면서 요청이 중단되었다.

### Analysis
